Workbook

Sheet 代號摘要
A1: 代號 | B1: 驗證情境 | C1: 反例 | D1: CSV 列數 | E1: 網站列數 | F1: 列數差 | G1: 漏列／多列說明 | H1: ✓ 數 | I1: ✗ 數 | J1: 不可核對數 | K1: 未填數 | L1: 狀態
A2: A017014321 | B2: 最長歷史（24 列），含同價續期 94→94 | D2: =COUNTIF(核對表!$A$2:$A$115,$A2) -> 24 | E2: 24 | F2: =IF(E2="","",E2-D2) -> 0 | H2: =COUNTIFS(核對表!$A$2:$A$115,$A2,核對表!$J$2:$J$115,"✓")+COUNTIFS(核對表!$A$2:$A$115,$A2,核對表!$K$2:$K$115,"✓")+COUNTIFS(核對表!$A$2:$A$115,$A2,核對表!$L$2:$L$115,"✓") -> 72 | I2: =COUNTIFS(核對表!$A$2:$A$115,$A2,核對表!$J$2:$J$115,"✗")+COUNTIFS(核對表!$A$2:$A$115,$A2,核對表!$K$2:$K$115,"✗")+COUNTIFS(核對表!$A$2:$A$115,$A2,核對表!$L$2:$L$115,"✗") -> 0 | J2: =COUNTIFS(核對表!$A$2:$A$115,$A2,核對表!$J$2:$J$115,"不可核對")+COUNTIFS(核對表!$A$2:$A$115,$A2,核對表!$K$2:$K$115,"不可核對")+COUNTIFS(核對表!$A$2:$A$115,$A2,核對表!$L$2:$L$115,"不可核對") -> 0 | K2: =COUNTIFS(核對表!$A$2:$A$115,$A2,核對表!$J$2:$J$115,"")+COUNTIFS(核對表!$A$2:$A$115,$A2,核對表!$K$2:$K$115,"")+COUNTIFS(核對表!$A$2:$A$115,$A2,核對表!$L$2:$L$115,"") -> 0 | L2: =IF(K2>0,"未完成",IF(I2>0,"有不符","完成")) -> 完成
A3: AC48092100 | B3: 一般多次降價 | D3: =COUNTIF(核對表!$A$2:$A$115,$A3) -> 8 | E3: 8 | F3: =IF(E3="","",E3-D3) -> 0 | H3: =COUNTIFS(核對表!$A$2:$A$115,$A3,核對表!$J$2:$J$115,"✓")+COUNTIFS(核對表!$A$2:$A$115,$A3,核對表!$K$2:$K$115,"✓")+COUNTIFS(核對表!$A$2:$A$115,$A3,核對表!$L$2:$L$115,"✓") -> 24 | I3: =COUNTIFS(核對表!$A$2:$A$115,$A3,核對表!$J$2:$J$115,"✗")+COUNTIFS(核對表!$A$2:$A$115,$A3,核對表!$K$2:$K$115,"✗")+COUNTIFS(核對表!$A$2:$A$115,$A3,核對表!$L$2:$L$115,"✗") -> 0 | J3: =COUNTIFS(核對表!$A$2:$A$115,$A3,核對表!$J$2:$J$115,"不可核對")+COUNTIFS(核對表!$A$2:$A$115,$A3,核對表!$K$2:$K$115,"不可核對")+COUNTIFS(核對表!$A$2:$A$115,$A3,核對表!$L$2:$L$115,"不可核對") -> 0 | K3: =COUNTIFS(核對表!$A$2:$A$115,$A3,核對表!$J$2:$J$115,"")+COUNTIFS(核對表!$A$2:$A$115,$A3,核對表!$K$2:$K$115,"")+COUNTIFS(核對表!$A$2:$A$115,$A3,核對表!$L$2:$L$115,"") -> 0 | L3: =IF(K3>0,"未完成",IF(I3>0,"有不符","完成")) -> 完成
A4: AC48867100 | B4: 終止後恢復支付（29.80 → 0 → 22.90） | C4: 是 | D4: =COUNTIF(核對表!$A$2:$A$115,$A4) -> 12 | E4: 12 | F4: =IF(E4="","",E4-D4) -> 0 | H4: =COUNTIFS(核對表!$A$2:$A$115,$A4,核對表!$J$2:$J$115,"✓")+COUNTIFS(核對表!$A$2:$A$115,$A4,核對表!$K$2:$K$115,"✓")+COUNTIFS(核對表!$A$2:$A$115,$A4,核對表!$L$2:$L$115,"✓") -> 36 | I4: =COUNTIFS(核對表!$A$2:$A$115,$A4,核對表!$J$2:$J$115,"✗")+COUNTIFS(核對表!$A$2:$A$115,$A4,核對表!$K$2:$K$115,"✗")+COUNTIFS(核對表!$A$2:$A$115,$A4,核對表!$L$2:$L$115,"✗") -> 0 | J4: =COUNTIFS(核對表!$A$2:$A$115,$A4,核對表!$J$2:$J$115,"不可核對")+COUNTIFS(核對表!$A$2:$A$115,$A4,核對表!$K$2:$K$115,"不可核對")+COUNTIFS(核對表!$A$2:$A$115,$A4,核對表!$L$2:$L$115,"不可核對") -> 0 | K4: =COUNTIFS(核對表!$A$2:$A$115,$A4,核對表!$J$2:$J$115,"")+COUNTIFS(核對表!$A$2:$A$115,$A4,核對表!$K$2:$K$115,"")+COUNTIFS(核對表!$A$2:$A$115,$A4,核對表!$L$2:$L$115,"") -> 0 | L4: =IF(K4>0,"未完成",IF(I4>0,"有不符","完成")) -> 完成
A5: AC48845100 | B5: 現行已終止 | D5: =COUNTIF(核對表!$A$2:$A$115,$A5) -> 9 | E5: 9 | F5: =IF(E5="","",E5-D5) -> 0 | H5: =COUNTIFS(核對表!$A$2:$A$115,$A5,核對表!$J$2:$J$115,"✓")+COUNTIFS(核對表!$A$2:$A$115,$A5,核對表!$K$2:$K$115,"✓")+COUNTIFS(核對表!$A$2:$A$115,$A5,核對表!$L$2:$L$115,"✓") -> 27 | I5: =COUNTIFS(核對表!$A$2:$A$115,$A5,核對表!$J$2:$J$115,"✗")+COUNTIFS(核對表!$A$2:$A$115,$A5,核對表!$K$2:$K$115,"✗")+COUNTIFS(核對表!$A$2:$A$115,$A5,核對表!$L$2:$L$115,"✗") -> 0 | J5: =COUNTIFS(核對表!$A$2:$A$115,$A5,核對表!$J$2:$J$115,"不可核對")+COUNTIFS(核對表!$A$2:$A$115,$A5,核對表!$K$2:$K$115,"不可核對")+COUNTIFS(核對表!$A$2:$A$115,$A5,核對表!$L$2:$L$115,"不可核對") -> 0 | K5: =COUNTIFS(核對表!$A$2:$A$115,$A5,核對表!$J$2:$J$115,"")+COUNTIFS(核對表!$A$2:$A$115,$A5,核對表!$K$2:$K$115,"")+COUNTIFS(核對表!$A$2:$A$115,$A5,核對表!$L$2:$L$115,"") -> 0 | L5: =IF(K5>0,"未完成",IF(I5>0,"有不符","完成")) -> 完成
A6: B009254100 | B6: 有價 → 暫停 → 終止 | C6: 是 | D6: =COUNTIF(核對表!$A$2:$A$115,$A6) -> 9 | E6: 9 | F6: =IF(E6="","",E6-D6) -> 0 | H6: =COUNTIFS(核對表!$A$2:$A$115,$A6,核對表!$J$2:$J$115,"✓")+COUNTIFS(核對表!$A$2:$A$115,$A6,核對表!$K$2:$K$115,"✓")+COUNTIFS(核對表!$A$2:$A$115,$A6,核對表!$L$2:$L$115,"✓") -> 27 | I6: =COUNTIFS(核對表!$A$2:$A$115,$A6,核對表!$J$2:$J$115,"✗")+COUNTIFS(核對表!$A$2:$A$115,$A6,核對表!$K$2:$K$115,"✗")+COUNTIFS(核對表!$A$2:$A$115,$A6,核對表!$L$2:$L$115,"✗") -> 0 | J6: =COUNTIFS(核對表!$A$2:$A$115,$A6,核對表!$J$2:$J$115,"不可核對")+COUNTIFS(核對表!$A$2:$A$115,$A6,核對表!$K$2:$K$115,"不可核對")+COUNTIFS(核對表!$A$2:$A$115,$A6,核對表!$L$2:$L$115,"不可核對") -> 0 | K6: =COUNTIFS(核對表!$A$2:$A$115,$A6,核對表!$J$2:$J$115,"")+COUNTIFS(核對表!$A$2:$A$115,$A6,核對表!$K$2:$K$115,"")+COUNTIFS(核對表!$A$2:$A$115,$A6,核對表!$L$2:$L$115,"") -> 0 | L6: =IF(K6>0,"未完成",IF(I6>0,"有不符","完成")) -> 完成
A7: BC23981100 | B7: 現行暫停，含 12 個月空窗 | C7: 是 | D7: =COUNTIF(核對表!$A$2:$A$115,$A7) -> 11 | E7: 11 | F7: =IF(E7="","",E7-D7) -> 0 | H7: =COUNTIFS(核對表!$A$2:$A$115,$A7,核對表!$J$2:$J$115,"✓")+COUNTIFS(核對表!$A$2:$A$115,$A7,核對表!$K$2:$K$115,"✓")+COUNTIFS(核對表!$A$2:$A$115,$A7,核對表!$L$2:$L$115,"✓") -> 33 | I7: =COUNTIFS(核對表!$A$2:$A$115,$A7,核對表!$J$2:$J$115,"✗")+COUNTIFS(核對表!$A$2:$A$115,$A7,核對表!$K$2:$K$115,"✗")+COUNTIFS(核對表!$A$2:$A$115,$A7,核對表!$L$2:$L$115,"✗") -> 0 | J7: =COUNTIFS(核對表!$A$2:$A$115,$A7,核對表!$J$2:$J$115,"不可核對")+COUNTIFS(核對表!$A$2:$A$115,$A7,核對表!$K$2:$K$115,"不可核對")+COUNTIFS(核對表!$A$2:$A$115,$A7,核對表!$L$2:$L$115,"不可核對") -> 0 | K7: =COUNTIFS(核對表!$A$2:$A$115,$A7,核對表!$J$2:$J$115,"")+COUNTIFS(核對表!$A$2:$A$115,$A7,核對表!$K$2:$K$115,"")+COUNTIFS(核對表!$A$2:$A$115,$A7,核對表!$L$2:$L$115,"") -> 0 | L7: =IF(K7>0,"未完成",IF(I7>0,"有不符","完成")) -> 完成
A8: A035680329 | B8: 1 個月空窗後終止 | C8: 是 | D8: =COUNTIF(核對表!$A$2:$A$115,$A8) -> 7 | E8: 7 | F8: =IF(E8="","",E8-D8) -> 0 | H8: =COUNTIFS(核對表!$A$2:$A$115,$A8,核對表!$J$2:$J$115,"✓")+COUNTIFS(核對表!$A$2:$A$115,$A8,核對表!$K$2:$K$115,"✓")+COUNTIFS(核對表!$A$2:$A$115,$A8,核對表!$L$2:$L$115,"✓") -> 21 | I8: =COUNTIFS(核對表!$A$2:$A$115,$A8,核對表!$J$2:$J$115,"✗")+COUNTIFS(核對表!$A$2:$A$115,$A8,核對表!$K$2:$K$115,"✗")+COUNTIFS(核對表!$A$2:$A$115,$A8,核對表!$L$2:$L$115,"✗") -> 0 | J8: =COUNTIFS(核對表!$A$2:$A$115,$A8,核對表!$J$2:$J$115,"不可核對")+COUNTIFS(核對表!$A$2:$A$115,$A8,核對表!$K$2:$K$115,"不可核對")+COUNTIFS(核對表!$A$2:$A$115,$A8,核對表!$L$2:$L$115,"不可核對") -> 0 | K8: =COUNTIFS(核對表!$A$2:$A$115,$A8,核對表!$J$2:$J$115,"")+COUNTIFS(核對表!$A$2:$A$115,$A8,核對表!$K$2:$K$115,"")+COUNTIFS(核對表!$A$2:$A$115,$A8,核對表!$L$2:$L$115,"") -> 0 | L8: =IF(K8>0,"未完成",IF(I8>0,"有不符","完成")) -> 完成
A9: BC05037209 | B9: 預告終止（2026-10-01） | C9: 是 | D9: =COUNTIF(核對表!$A$2:$A$115,$A9) -> 6 | E9: 6 | F9: =IF(E9="","",E9-D9) -> 0 | H9: =COUNTIFS(核對表!$A$2:$A$115,$A9,核對表!$J$2:$J$115,"✓")+COUNTIFS(核對表!$A$2:$A$115,$A9,核對表!$K$2:$K$115,"✓")+COUNTIFS(核對表!$A$2:$A$115,$A9,核對表!$L$2:$L$115,"✓") -> 18 | I9: =COUNTIFS(核對表!$A$2:$A$115,$A9,核對表!$J$2:$J$115,"✗")+COUNTIFS(核對表!$A$2:$A$115,$A9,核對表!$K$2:$K$115,"✗")+COUNTIFS(核對表!$A$2:$A$115,$A9,核對表!$L$2:$L$115,"✗") -> 0 | J9: =COUNTIFS(核對表!$A$2:$A$115,$A9,核對表!$J$2:$J$115,"不可核對")+COUNTIFS(核對表!$A$2:$A$115,$A9,核對表!$K$2:$K$115,"不可核對")+COUNTIFS(核對表!$A$2:$A$115,$A9,核對表!$L$2:$L$115,"不可核對") -> 0 | K9: =COUNTIFS(核對表!$A$2:$A$115,$A9,核對表!$J$2:$J$115,"")+COUNTIFS(核對表!$A$2:$A$115,$A9,核對表!$K$2:$K$115,"")+COUNTIFS(核對表!$A$2:$A$115,$A9,核對表!$L$2:$L$115,"") -> 0 | L9: =IF(K9>0,"未完成",IF(I9>0,"有不符","完成")) -> 完成
A10: AB47689100 | B10: 預告調價（2026-10-01 → 7.90） | C10: 是 | D10: =COUNTIF(核對表!$A$2:$A$115,$A10) -> 12 | E10: 12 | F10: =IF(E10="","",E10-D10) -> 0 | H10: =COUNTIFS(核對表!$A$2:$A$115,$A10,核對表!$J$2:$J$115,"✓")+COUNTIFS(核對表!$A$2:$A$115,$A10,核對表!$K$2:$K$115,"✓")+COUNTIFS(核對表!$A$2:$A$115,$A10,核對表!$L$2:$L$115,"✓") -> 36 | I10: =COUNTIFS(核對表!$A$2:$A$115,$A10,核對表!$J$2:$J$115,"✗")+COUNTIFS(核對表!$A$2:$A$115,$A10,核對表!$K$2:$K$115,"✗")+COUNTIFS(核對表!$A$2:$A$115,$A10,核對表!$L$2:$L$115,"✗") -> 0 | J10: =COUNTIFS(核對表!$A$2:$A$115,$A10,核對表!$J$2:$J$115,"不可核對")+COUNTIFS(核對表!$A$2:$A$115,$A10,核對表!$K$2:$K$115,"不可核對")+COUNTIFS(核對表!$A$2:$A$115,$A10,核對表!$L$2:$L$115,"不可核對") -> 0 | K10: =COUNTIFS(核對表!$A$2:$A$115,$A10,核對表!$J$2:$J$115,"")+COUNTIFS(核對表!$A$2:$A$115,$A10,核對表!$K$2:$K$115,"")+COUNTIFS(核對表!$A$2:$A$115,$A10,核對表!$L$2:$L$115,"") -> 0 | L10: =IF(K10>0,"未完成",IF(I10>0,"有不符","完成")) -> 完成
A11: BC26467100 | B11: 預告列成分欄損毀；metadata 不得取該列 | C11: 是 | D11: =COUNTIF(核對表!$A$2:$A$115,$A11) -> 10 | E11: 10 | F11: =IF(E11="","",E11-D11) -> 0 | H11: =COUNTIFS(核對表!$A$2:$A$115,$A11,核對表!$J$2:$J$115,"✓")+COUNTIFS(核對表!$A$2:$A$115,$A11,核對表!$K$2:$K$115,"✓")+COUNTIFS(核對表!$A$2:$A$115,$A11,核對表!$L$2:$L$115,"✓") -> 30 | I11: =COUNTIFS(核對表!$A$2:$A$115,$A11,核對表!$J$2:$J$115,"✗")+COUNTIFS(核對表!$A$2:$A$115,$A11,核對表!$K$2:$K$115,"✗")+COUNTIFS(核對表!$A$2:$A$115,$A11,核對表!$L$2:$L$115,"✗") -> 0 | J11: =COUNTIFS(核對表!$A$2:$A$115,$A11,核對表!$J$2:$J$115,"不可核對")+COUNTIFS(核對表!$A$2:$A$115,$A11,核對表!$K$2:$K$115,"不可核對")+COUNTIFS(核對表!$A$2:$A$115,$A11,核對表!$L$2:$L$115,"不可核對") -> 0 | K11: =COUNTIFS(核對表!$A$2:$A$115,$A11,核對表!$J$2:$J$115,"")+COUNTIFS(核對表!$A$2:$A$115,$A11,核對表!$K$2:$K$115,"")+COUNTIFS(核對表!$A$2:$A$115,$A11,核對表!$L$2:$L$115,"") -> 0 | L11: =IF(K11>0,"未完成",IF(I11>0,"有不符","完成")) -> 完成
A12: A020296321 | B12: 首列 0 元後首次有價（first_priced） | C12: 是 | D12: =COUNTIF(核對表!$A$2:$A$115,$A12) -> 6 | E12: 6 | F12: =IF(E12="","",E12-D12) -> 0 | H12: =COUNTIFS(核對表!$A$2:$A$115,$A12,核對表!$J$2:$J$115,"✓")+COUNTIFS(核對表!$A$2:$A$115,$A12,核對表!$K$2:$K$115,"✓")+COUNTIFS(核對表!$A$2:$A$115,$A12,核對表!$L$2:$L$115,"✓") -> 18 | I12: =COUNTIFS(核對表!$A$2:$A$115,$A12,核對表!$J$2:$J$115,"✗")+COUNTIFS(核對表!$A$2:$A$115,$A12,核對表!$K$2:$K$115,"✗")+COUNTIFS(核對表!$A$2:$A$115,$A12,核對表!$L$2:$L$115,"✗") -> 0 | J12: =COUNTIFS(核對表!$A$2:$A$115,$A12,核對表!$J$2:$J$115,"不可核對")+COUNTIFS(核對表!$A$2:$A$115,$A12,核對表!$K$2:$K$115,"不可核對")+COUNTIFS(核對表!$A$2:$A$115,$A12,核對表!$L$2:$L$115,"不可核對") -> 0 | K12: =COUNTIFS(核對表!$A$2:$A$115,$A12,核對表!$J$2:$J$115,"")+COUNTIFS(核對表!$A$2:$A$115,$A12,核對表!$K$2:$K$115,"")+COUNTIFS(核對表!$A$2:$A$115,$A12,核對表!$L$2:$L$115,"") -> 0 | L12: =IF(K12>0,"未完成",IF(I12>0,"有不符","完成")) -> 完成
A13: 合計 | D13: =SUM(D2:D12) -> 114 | H13: =SUM(H2:H12) -> 342 | I13: =SUM(I2:I12) -> 0 | J13: =SUM(J2:J12) -> 0 | K13: =SUM(K2:K12) -> 0

Sheet 說明
A1: 健保藥價歷史 golden 代號人工核對表
A2: 資料來源：健保署「健保用藥品項查詢項目檔」2026-09-11 下載之凍結快照（tests/fixtures/source_snapshot_2026-09-11.csv）
A3: 目的：以獨立來源（健保署藥品查詢網站）逐列核對本站 ETL 對 11 個代號的判讀是否正確（plan.md D1）。
A5: 填寫方式
A6: 1. 只填黃底格子；其他格子為本站輸出，請勿修改。
A7: 2. 「核對表」每列三個核對欄請填：✓（相符）／✗（不符）／不可核對（網站未提供該資訊）。
A8: 3. 標「不可核對」的列，請在備註寫明替代核對方式（例：已抽核 CSV 原檔）。
A9: 4. 「代號摘要」請填網站上看到的列數；與 CSV 列數不同時，請寫明漏列或多列。
A10: 5. 最下方填寫核對人與核對日期。
A12: 時限：AB47689100、BC05037209 的預告生效日為 2026-10-01，請於該日前完成（網站可能不再顯示預告狀態）。
A14: 範例列（格式示意，非實際資料）
A15: 代號 | B15: 序 | C15: 有效起日 | D15: 有效迄日 | E15: CSV 支付價原字串 | F15: 本站判定狀態 | G15: 本站事件 | H15: 前次有價 | I15: 變動 % | J15: 網站：起迄日相符 | K15: 網站：支付價相符 | L15: 狀態判定同意 | M15: 備註
A16: AC48867100 | B16: 4 | C16: 2017-12-01 | D16: 2018-04-30 | E16: 22.90 | F16: 有價 | G16: 恢復支付（跨越停止期間） | H16: 29.80 | I16: -23.15 | J16: ✓ | K16: ✓ | L16: ✓ | M16: 網站顯示 22.9，與原字串 22.90 數值相符
A18: 核對人 | B18: liangRxdev
A19: 核對日期（YYYY-MM-DD） | B19: 2026-09-11

Sheet 核對表
A1: 代號 | B1: 序 | C1: 有效起日 | D1: 有效迄日 | E1: CSV 支付價原字串 | F1: 本站判定狀態 | G1: 本站事件 | H1: 前次有價 | I1: 變動 % | J1: 網站：起迄日相符 | K1: 網站：支付價相符 | L1: 狀態判定同意 | M1: 備註
A2: A017014321 | B2: 1 | C2: 1997-08-01 | D2: 1999-03-31 | E2: 94.00 | F2: 有價 | G2: 首筆 | J2: ✓ | K2: ✓ | L2: ✓
A3: A017014321 | B3: 2 | C3: 1999-04-01 | D3: 1999-09-30 | E3: 94.00 | F3: 有價 | G3: 未變動 | H3: 94.00 | J3: ✓ | K3: ✓ | L3: ✓
A4: A017014321 | B4: 3 | C4: 1999-10-01 | D4: 2000-03-31 | E4: 88.36 | F4: 有價 | G4: 降價 | H4: 94.00 | I4: -6.00 | J4: ✓ | K4: ✓ | L4: ✓
A5: A017014321 | B5: 4 | C5: 2000-04-01 | D5: 2000-09-30 | E5: 74.57 | F5: 有價 | G5: 降價 | H5: 88.36 | I5: -15.61 | J5: ✓ | K5: ✓ | L5: ✓
A6: A017014321 | B6: 5 | C6: 2000-10-01 | D6: 2001-03-31 | E6: 82.72 | F6: 有價 | G6: 漲價 | H6: 74.57 | I6: 10.93 | J6: ✓ | K6: ✓ | L6: ✓
A7: A017014321 | B7: 6 | C7: 2001-04-01 | D7: 2001-09-30 | E7: 76.63 | F7: 有價 | G7: 降價 | H7: 82.72 | I7: -7.36 | J7: ✓ | K7: ✓ | L7: ✓
A8: A017014321 | B8: 7 | C8: 2001-10-01 | D8: 2003-02-28 | E8: 75.20 | F8: 有價 | G8: 降價 | H8: 76.63 | I8: -1.87 | J8: ✓ | K8: ✓ | L8: ✓
A9: A017014321 | B9: 8 | C9: 2003-03-01 | D9: 2006-10-31 | E9: 69.00 | F9: 有價 | G9: 降價 | H9: 75.20 | I9: -8.24 | J9: ✓ | K9: ✓ | L9: ✓
A10: A017014321 | B10: 9 | C10: 2006-11-01 | D10: 2007-08-31 | E10: 61.00 | F10: 有價 | G10: 降價 | H10: 69.00 | I10: -11.59 | J10: ✓ | K10: ✓ | L10: ✓
A11: A017014321 | B11: 10 | C11: 2007-09-01 | D11: 2009-09-30 | E11: 56.00 | F11: 有價 | G11: 降價 | H11: 61.00 | I11: -8.20 | J11: ✓ | K11: ✓ | L11: ✓
A12: A017014321 | B12: 11 | C12: 2009-10-01 | D12: 2011-11-30 | E12: 43.40 | F12: 有價 | G12: 降價 | H12: 56.00 | I12: -22.50 | J12: ✓ | K12: ✓ | L12: ✓
A13: A017014321 | B13: 12 | C13: 2011-12-01 | D13: 2014-06-30 | E13: 40.90 | F13: 有價 | G13: 降價 | H13: 43.40 | I13: -5.76 | J13: ✓ | K13: ✓ | L13: ✓
A14: A017014321 | B14: 13 | C14: 2014-07-01 | D14: 2015-03-31 | E14: 39.80 | F14: 有價 | G14: 降價 | H14: 40.90 | I14: -2.69 | J14: ✓ | K14: ✓ | L14: ✓
A15: A017014321 | B15: 14 | C15: 2015-04-01 | D15: 2016-03-31 | E15: 36.10 | F15: 有價 | G15: 降價 | H15: 39.80 | I15: -9.30 | J15: ✓ | K15: ✓ | L15: ✓
... A25: A017014321 | B25: 24 | C25: 2026-04-01 | D25: （持續有效） | E25: 28.10 | F25: 有價 | G25: 降價 | H25: 29.00 | I25: -3.10 | J25: ✓ | K25: ✓ | L25: ✓
A26: AC48092100 | B26: 1 | C26: 2016-08-01 | D26: 2017-03-31 | E26: 9.90 | F26: 有價 | G26: 首筆 | J26: ✓ | K26: ✓ | L26: ✓
A27: AC48092100 | B27: 2 | C27: 2017-04-01 | D27: 2018-04-30 | E27: 8.80 | F27: 有價 | G27: 降價 | H27: 9.90 | I27: -11.11 | J27: ✓ | K27: ✓ | L27: ✓
A28: AC48092100 | B28: 3 | C28: 2018-05-01 | D28: 2019-03-31 | E28: 7.50 | F28: 有價 | G28: 降價 | H28: 8.80 | I28: -14.77 | J28: ✓ | K28: ✓ | L28: ✓
A29: AC48092100 | B29: 4 | C29: 2019-04-01 | D29: 2020-09-30 | E29: 6.70 | F29: 有價 | G29: 降價 | H29: 7.50 | I29: -10.67 | J29: ✓ | K29: ✓ | L29: ✓
A30: AC48092100 | B30: 5 | C30: 2020-10-01 | D30: 2021-12-31 | E30: 6.20 | F30: 有價 | G30: 降價 | H30: 6.70 | I30: -7.46 | J30: ✓ | K30: ✓ | L30: ✓
A31: AC48092100 | B31: 6 | C31: 2022-01-01 | D31: 2023-03-31 | E31: 5.30 | F31: 有價 | G31: 降價 | H31: 6.20 | I31: -14.52 | J31: ✓ | K31: ✓ | L31: ✓
A32: AC48092100 | B32: 7 | C32: 2023-04-01 | D32: 2024-03-31 | E32: 4.61 | F32: 有價 | G32: 降價 | H32: 5.30 | I32: -13.02 | J32: ✓ | K32: ✓ | L32: ✓
A33: AC48092100 | B33: 8 | C33: 2024-04-01 | D33: （持續有效） | E33: 4.12 | F33: 有價 | G33: 降價 | H33: 4.61 | I33: -10.63 | J33: ✓ | K33: ✓ | L33: ✓
A34: AC48867100 | B34: 1 | C34: 2013-08-01 | D34: 2014-04-30 | E34: 32.30 | F34: 有價 | G34: 首筆 | J34: ✓ | K34: ✓ | L34: ✓
A35: AC48867100 | B35: 2 | C35: 2014-05-01 | D35: 2014-12-31 | E35: 29.80 | F35: 有價 | G35: 降價 | H35: 32.30 | I35: -7.74 | J35: ✓ | K35: ✓ | L35: ✓
A36: AC48867100 | B36: 3 | C36: 2015-01-01 | D36: 2017-11-30 | E36: 0.00 | F36: 健保支付價 0 元（已終止支付） | G36: 終止支付 | H36: 29.80 | J36: ✓ | K36: ✓ | L36: ✓
A37: AC48867100 | B37: 4 | C37: 2017-12-01 | D37: 2018-04-30 | E37: 22.90 | F37: 有價 | G37: 恢復支付（跨越停止期間） | H37: 29.80 | I37: -23.15 | J37: ✓ | K37: ✓ | L37: ✓
A38: AC48867100 | B38: 5 | C38: 2018-05-01 | D38: 2019-03-31 | E38: 20.50 | F38: 有價 | G38: 降價 | H38: 22.90 | I38: -10.48 | J38: ✓ | K38: ✓ | L38: ✓
A39: AC48867100 | B39: 6 | C39: 2019-04-01 | D39: 2020-09-30 | E39: 18.90 | F39: 有價 | G39: 降價 | H39: 20.50 | I39: -7.80 | J39: ✓ | K39: ✓ | L39: ✓
A40: AC48867100 | B40: 7 | C40: 2020-10-01 | D40: 2021-12-31 | E40: 20.40 | F40: 有價 | G40: 漲價 | H40: 18.90 | I40: 7.94 | J40: ✓ | K40: ✓ | L40: ✓
A41: AC48867100 | B41: 8 | C41: 2022-01-01 | D41: 2023-03-31 | E41: 18.40 | F41: 有價 | G41: 降價 | H41: 20.40 | I41: -9.80 | J41: ✓ | K41: ✓ | L41: ✓
A42: AC48867100 | B42: 9 | C42: 2023-04-01 | D42: 2024-03-31 | E42: 16.30 | F42: 有價 | G42: 降價 | H42: 18.40 | I42: -11.41 | J42: ✓ | K42: ✓ | L42: ✓
A43: AC48867100 | B43: 10 | C43: 2024-04-01 | D43: 2025-03-31 | E43: 14.60 | F43: 有價 | G43: 降價 | H43: 16.30 | I43: -10.43 | J43: ✓ | K43: ✓ | L43: ✓
A44: AC48867100 | B44: 11 | C44: 2025-04-01 | D44: 2026-03-31 | E44: 13.50 | F44: 有價 | G44: 降價 | H44: 14.60 | I44: -7.53 | J44: ✓ | K44: ✓ | L44: ✓
A45: AC48867100 | B45: 12 | C45: 2026-04-01 | D45: （持續有效） | E45: 12.50 | F45: 有價 | G45: 降價 | H45: 13.50 | I45: -7.41 | J45: ✓ | K45: ✓ | L45: ✓
A46: AC48845100 | B46: 1 | C46: 2013-08-01 | D46: 2014-06-30 | E46: 4.80 | F46: 有價 | G46: 首筆 | J46: ✓ | K46: ✓ | L46: ✓
A47: AC48845100 | B47: 2 | C47: 2014-07-01 | D47: 2015-03-31 | E47: 5.70 | F47: 有價 | G47: 漲價 | H47: 4.80 | I47: 18.75 | J47: ✓ | K47: ✓ | L47: ✓
A48: AC48845100 | B48: 3 | C48: 2015-04-01 | D48: 2016-03-31 | E48: 5.40 | F48: 有價 | G48: 降價 | H48: 5.70 | I48: -5.26 | J48: ✓ | K48: ✓ | L48: ✓
A49: AC48845100 | B49: 4 | C49: 2016-04-01 | D49: 2017-03-31 | E49: 5.30 | F49: 有價 | G49: 降價 | H49: 5.40 | I49: -1.85 | J49: ✓ | K49: ✓ | L49: ✓
...
